Workbook

Sheet BOQ
A1: BILL OF QUANTITIES — DELPHI PROJECT AZURE INFRASTRUCTURE
A2: # | B2: Description / Specification | C2: Qty | D2: Unit | E2: Unit Cost (USD) | F2: Monthly (USD)
A3: 1. COMPUTE
A4: 1.1 | B4: AKS Standard Tier — Control Plane SLA (prod-aks-cluster) | C4: 1 | D4: Cluster/mo | E4: 73 | F4: =C4*E4 -> 73
A5: 1.2 | B5: AKS Node VM — Standard_D2s_v3 (2 vCPU, 8 GB RAM) | C5: 1 | D5: VM/mo | E5: 83.28 | F5: =C5*E5 -> 83.28
A6: 1.3 | B6: App Service Plan S2 — Linux (2 instances per tfvars) | C6: 2 | D6: Instance/mo | E6: 73 | F6: =C6*E6 -> 146
A7: Subtotal — Compute | F7: =SUM(F3:F6) -> 302.28
A8: 2. STORAGE
A9: 2.1 | B9: AKS OS Disk — Premium SSD P10 (128 GB) | C9: 1 | D9: Disk/mo | E9: 17 | F9: =C9*E9 -> 17
A10: 2.2 | B10: Kubernetes PVC — Premium SSD P10 (10 GB, delphi-pvc) | C10: 1 | D10: Disk/mo | E10: 19 | F10: =C10*E10 -> 19
A11: 2.3 | B11: ACR Premium Storage — included 500 GB, est. usage < 500 GB | C11: 1 | D11: Registry/mo | E11: 0 | F11: 0
A12: 2.4 | B12: Diagnostic Storage Account — Standard GRS (~5 GB/mo) | C12: 5 | D12: GB/mo | E12: 0.023 | F12: =C12*E12 -> 0.115
A13: Subtotal — Storage | F13: =SUM(F8:F12) -> 36.115
A14: 3. CONTAINER REGISTRY
A15: 3.1 | B15: Azure Container Registry — Premium SKU (required for private endpoint) | C15: 1 | D15: Registry/mo | E15: 110 | F15: =C15*E15 -> 110
A16: Subtotal — Container Registry | F16: =SUM(F14:F15) -> 110
A17: 4. NETWORKING
A18: 4.1 | B18: Virtual Network (prod-vnet) | C18: 1 | D18: VNet/mo | E18: 0 | F18: 0
A19: 4.2 | B19: Private Endpoint — ACR | C19: 1 | D19: Endpoint/mo | E19: 7.44 | F19: =C19*E19 -> 7.44
A20: 4.3 | B20: Private Endpoint — Key Vault | C20: 1 | D20: Endpoint/mo | E20: 7.44 | F20: =C20*E20 -> 7.44
A21: 4.4 | B21: Private Endpoint — App Service | C21: 1 | D21: Endpoint/mo | E21: 7.44 | F21: =C21*E21 -> 7.44
A22: 4.5 | B22: Private DNS Zone — ACR (privatelink.azurecr.io) | C22: 1 | D22: Zone/mo | E22: 0.5 | F22: =C22*E22 -> 0.5
A23: 4.6 | B23: Private DNS Zone — Key Vault (privatelink.vaultcore.azure.net) | C23: 1 | D23: Zone/mo | E23: 0.5 | F23: =C23*E23 -> 0.5
A24: 4.7 | B24: Private DNS Zone — App Service (privatelink.azurewebsites.net) | C24: 1 | D24: Zone/mo | E24: 0.5 | F24: =C24*E24 -> 0.5
A25: 4.8 | B25: Standard Load Balancer — AKS Internal LB | C25: 1 | D25: LB/mo | E25: 18.6 | F25: =C25*E25 -> 18.6
A26: 4.9 | B26: Public IP Address — AKS Outbound NAT | C26: 1 | D26: IP/mo | E26: 2.976 | F26: =C26*E26 -> 2.976
A27: 4.10 | B27: Data Transfer Outbound — est. 50 GB/mo (first 5 GB free) | C27: 45 | D27: GB/mo | E27: 0.087 | F27: =C27*E27 -> 3.915
A28: Subtotal — Networking | F28: =SUM(F17:F27) -> 49.311
A29: 5. KEY VAULT
A30: 5.1 | B30: Key Vault — Standard SKU (delphi-prod-kv) | C30: 1 | D30: Vault/mo | E30: 0 | F30: 0
A31: 5.2 | B31: Key Vault Secret Operations — est. 50k ops/mo | C31: 5 | D31: 10k ops/mo | E31: 0.03 | F31: =C31*E31 -> 0.15
A32: 5.3 | B32: Key Vault Certificate Renewals — est. 2/mo | C32: 2 | D32: Certs/mo | E32: 3 | F32: =C32*E32 -> 6
A33: Subtotal — Key Vault | F33: =SUM(F29:F32) -> 6.15
A34: 6. MONITORING
A35: 6.1 | B35: Log Analytics Workspace — Pay-As-You-Go, est. 5 GB/mo ingestion | C35: 5 | D35: GB/mo | E35: 2.76 | F35: =C35*E35 -> 13.8
A36: 6.2 | B36: Log Analytics Retention — beyond 31-day free tier, est. 50 GB | C36: 50 | D36: GB/mo | E36: 0.1 | F36: =C36*E36 -> 5
A37: 6.3 | B37: AKS Container Insights (monitor_metrics enabled) | C37: 1 | D37: Cluster/mo | E37: 0 | F37: 0
A38: 6.4 | B38: Application Insights — Workspace-based, est. 2 GB/mo telemetry | C38: 2 | D38: GB/mo | E38: 2.76 | F38: =C38*E38 -> 5.52
A39: 6.5 | B39: Azure Monitor Alert Rules — est. 10 rules | C39: 10 | D39: Rules/mo | E39: 0.1 | F39: =C39*E39 -> 1
A40: Subtotal — Monitoring | F40: =SUM(F34:F39) -> 25.32
...

Sheet Cost Summary
A1: COST SUMMARY DASHBOARD — DELPHI AZURE INFRASTRUCTURE
A2: Category | B2: Monthly (USD) | C2: Annual (USD) | D2: % of Total
A3: Compute | B3: =BOQ!F7 -> 302.28 | C3: =B3*12 -> 3627.36 | D3: =B3/B11 -> 0.48979036
A4: Storage | B4: =BOQ!F13 -> 36.115 | C4: =B4*12 -> 433.38 | D4: =B4/B11 -> 0.058517861
A5: Container Registry | B5: =BOQ!F16 -> 110 | C5: =B5*12 -> 1320 | D5: =B5/B11 -> 0.17823521
A6: Networking | B6: =BOQ!F28 -> 49.311 | C6: =B6*12 -> 591.732 | D6: =B6/B11 -> 0.079899605
A7: Key Vault | B7: =BOQ!F33 -> 6.15 | C7: =B7*12 -> 73.8 | D7: =B7/B11 -> 0.0099649687
A8: Monitoring | B8: =BOQ!F40 -> 25.32 | C8: =B8*12 -> 303.84 | D8: =B8/B11 -> 0.041026505
A9: Security | B9: =BOQ!F47 -> 44.274 | C9: =B9*12 -> 531.288 | D9: =B9/B11 -> 0.071738053
A10: DevOps & Pipelines | B10: =BOQ!F52 -> 43.712 | C10: =B10*12 -> 524.544 | D10: =B10/B11 -> 0.070827433
A11: TOTAL | B11: =SUM(B3:B10) -> 617.162 | C11: =B11*12 -> 7405.944 | D11: 100.0%
